Workbook

Sheet 生產達成率(目標)
A1: 料號 | B1: 品名 | C1: 生產達成率(目標)
A2: A1020 | B2: 大圓草莓-新 | C2: 1
A3: A1032 | B3: 小圓草莓(1*170g) | C3: 1
A4: A1040 | B4: 開心草莓果醬(1*430g) | C4: 1
A5: A1050 | B5: 梨山草莓果醬(1*430g) | C5: 1
A6: A2020 | B6: PET大花生(1*400g) | C6: 1
A7: A2040 | B7: PET瓶花生(1*340g) | C7: 1
A8: A2050 | B8: PET瓶花生(粒)(1*340g) | C8: 1
A9: A2060 | B9: 顆粒花生醬(全) | C9: 1
A10: A3010 | B10: 小藍莓1*260G | C10: 1
A11: A3011 | B11: 小藍莓1*260G | C11: 1
A12: B1011 | B12: ＃1草莓(1*3.2kg) | C12: 1
A13: B1020 | B13: ＃1蜂草(1*3.5kg) | C13: 1
... A116: D1792 | B116: 柚皮糖B | C116: 1
A117: 111033 | B117: 加糖柑橘果皮(柳橙) | C117: 1
A118: 111010 | B118: 糖漬桔皮絲 | C118: 1
A119: 111050 | B119: 糖漬檸檬絲 | C119: 1
A120: 151010 | B120: 蜜紅果6m/m | C120: 1
A121: 152010 | B121: 蜜綠果6m/m | C121: 1
A122: 153010 | B122: 蜜桔皮6m/m | C122: 1
A123: 153081 | B123: 已殺菁桔皮(進口) | C123: 1
A124: 159040 | B124: 蘿蔔RE | C124: 1
A125: F0020 | B125: 蜜餞水果(1*1kg) | C125: 1
A126: D0191-1 | B126: 蘋果餡(1*6Kg) | C126: 1
A127: D1791 | B127: 柚皮糖 | C127: 1
A128: B2021-1 | B128: ＃1花生(粒)(1*2.8kg) | C128: 1
A129: D0132-1 | B129: 綜合莓果餡(1*6Kg) | C129: 1
A130: D0594 | B130: 柚皮鮮果乾(100g) | C130: 1
A131: D9950 | B131: 紅棗醬(1*210G) | C131: 1
A132: C3020-1 | B132: 藍莓餡（大）(1*9.08kg) | C132: 1
A133: D1520 | B133: 花生醬(1*290g) | C133: 1
A134: D1521 | B134: 花生醬(粒)(1*270g) | C134: 1
A135: B2041 | B135: ＃2花生（粒）(1*800g) | C135: 1
A136: C3080 | B136: 上好佳藍莓餡(大)4.5KG | C136: 1
... A139: E0120 | B139: 佳樂美細花(1*340g) | C139: 1
A140: 155121 | B140: 糖蜜柚泥 | C140: 1
A141: Z1001 | B141: 桔光抹醬(1*190g) | C141: 1
A142: D0141 | B142: 白桃烏龍餡(1*6Kg) | C142: 1
A143: D0174 | B143: 楊枝甘露餡(1*6Kg) | C143: 1
A144: D0390 | B144: 化應子(1*2.5KG) | C144: 1
...

Sheet 112年全品項生產鍋數
A1: 112年鍋數生產均數表(實際半成品數／鍋數）
A2: 料號 | B2: 品名 | C2: 規格 (kg) | D2: 平均1鍋生產量 | E2: 第1季調整 | F2: 第2季調整 | G2: 2025Q1調整 | H2: 單位 | J2: 說明： | K2: 左項生產參數由生產單位定期檢討更新。
A3: A1020 | B3: 大圓草莓-新 | C3: 0.44 | D3: 332.4 | E3: 336.5 | F3: 336.5 | G3: 344 | H3: 瓶
A4: A1032 | B4: 小圓草莓(1*170g) | C4: 0.17 | D4: 883.4 | E4: 883.4 | F4: 883.4 | G4: 912.6 | H4: 瓶
A5: A1040 | B5: 開心草莓果醬(1*430g) | C5: 0.43 | D5: 353.3 | E5: 353.3 | F5: 353.3 | G5: 364 | H5: 瓶
A6: A1040-1 | B6: 開心草莓果醬(1*430g) | C6: 0.43 | G6: 364 | H6: 瓶
A7: A1050 | B7: 梨山草莓果醬(1*430g) | C7: 0.43 | D7: 331.3 | E7: 331.3 | F7: 331.3 | G7: 340.4 | H7: 瓶
A8: A2020 | B8: PET大花生(1*400g) | C8: 0.4 | D8: 310.5 | E8: 310.5 | F8: 310.5 | G8: 309.2 | H8: 瓶 | I8: 調降
A9: A2040 | B9: PET瓶花生(1*340g) | C9: 0.34 | D9: 368.3 | E9: 368.3 | F9: 357 | G9: 358.3 | H9: 瓶
A10: A2040-1 | B10: PET瓶花生(1*340g) | C10: 0.34 | D10: 368.3 | E10: 368.3 | F10: 357 | G10: 358.3 | H10: 瓶
A11: A2050 | B11: PET瓶花生(粒)(1*340g) | C11: 0.34 | D11: 372.3 | E11: 360 | F11: 360 | G11: 366 | H11: 瓶
A12: A2060 | B12: 顆粒花生醬(全) | C12: 0.34 | D12: 360.5 | E12: 360.5 | F12: 360 | G12: 364.6 | H12: 瓶
A13: A3010 | B13: 小藍莓1*260G | C13: 0.26 | D13: 570.4 | E13: 570.4 | F13: 570.4 | G13: 584.3 | H13: 瓶
A14: A3011 | B14: 小藍莓1*260G | C14: 0.26 | D14: 551.9 | E14: 570.4 | F14: 570.4 | G14: 592 | H14: 瓶
A15: B1011 | B15: ＃1草莓(1*3.2kg) | C15: 3.2 | D15: 46.2 | E15: 46.2 | F15: 46.2 | G15: 46.8 | H15: 罐
A16: B1020 | B16: ＃1蜂草(1*3.5kg) | C16: 3.5 | D16: 39.6 | F16: 39.6 | G16: 39.6 | H16: 罐
A17: B1030 | B17: ＃1草莓原漿(1*3.5kg) | C17: 3.5 | D17: 40.7 | F17: 40.7 | G17: 40.7 | H17: 罐
A18: B1031 | B18: ＃1草莓原漿(1*3.4kg) | C18: 3.4 | D18: 42.2 | E18: 42.2 | F18: 42.2 | G18: 43 | H18: 罐
A19: B1040 | B19: #2草莓果醬(1*900g) | C19: 0.9 | D19: 159.1 | E19: 159.1 | F19: 159.1 | G19: 160.5 | H19: 罐
A20: B1041 | B20: 上好佳草莓餡(1*900g) | C20: 0.9 | D20: 168 | F20: 168 | G20: 173 | H20: 罐
A21: B2011 | B21: ＃1花生(1*2.8kg) | C21: 2.8 | D21: 44.9 | E21: 46 | F21: 44.7 | G21: 44.5 | H21: 罐 | I21: 調降
A22: B2021 | B22: ＃1花生(粒)(1*2.8kg) | C22: 2.8 | D22: 44.9 | E22: 44.9 | F22: 44.9 | G22: 44.2 | H22: 罐 | I22: 調降
A23: B2030 | B23: ＃2花生(1*900g) | C23: 0.9 | D23: 139.2 | F23: 139.2 | G23: 139.2 | H23: 罐
A24: B2031 | B24: ＃2花生(1*800g) | C24: 0.8 | D24: 154.2 | E24: 154.2 | F24: 154.2 | G24: 157.7 | H24: 罐
A25: B2040 | B25: ＃2花生（粒）(1*900g) | C25: 0.9 | D25: 140.6 | E25: 140.6 | F25: 139 | G25: 139.3 | H25: 罐
A26: B3011 | B26: ＃1藍莓(1*3.2kg) | C26: 3.2 | D26: 45.8 | E26: 46.2 | F26: 46.2 | G26: 47.5 | H26: 罐
A27: B3020 | B27: ＃2藍莓(1*900g) | C27: 0.9 | D27: 162.5 | E27: 165 | F27: 165 | G27: 163 | H27: 罐 | I27: 調降
A28: B5011 | B28: ＃1桔子(1*3.2kg) | C28: 3.2 | D28: 46.8 | E28: 46.8 | F28: 46.8 | G28: 46.4 | H28: 罐 | I28: 調降
A29: C1010 | B29: 草莓果醬(桶)(1*9.5KG) | C29: 9.5 | D29: 15.6 | E29: 15.6 | F29: 15.6 | G29: 16.6 | H29: 桶
A30: C1020 | B30: 天天開心草莓餡4.5KG | C30: 4.5 | D30: 34.8 | E30: 34.8 | F30: 34.8 | G30: 36.3 | H30: 桶
A31: C1030 | B31: 上好佳草莓餡4.5KG | C31: 4.5 | D31: 34.8 | E31: 34.8 | F31: 34.8 | G31: 36.3 | H31: 桶
A32: C3010 | B32: 藍莓餡（小）(1*4.5kg) | C32: 4.5 | D32: 34.5 | E32: 34 | F32: 34 | G32: 35 | H32: 桶
A33: C3020 | B33: 藍莓餡（大）(1*9.08kg) | C33: 9.08 | D33: 16.6 | E33: 16.6 | F33: 16.6 | G33: 17.8 | H33: 桶
A34: C3070 | B34: 天天開心藍莓餡4.5KG | C34: 4.5 | D34: 36.1 | E34: 36.1 | F34: 36.1 | G34: 36.8 | H34: 桶
A35: C5010 | B35: 天天開心柳橙餡4.5KG | C35: 4.5 | D35: 34 | E35: 34 | F35: 34 | G35: 34.9 | H35: 桶
A36: C5020 | B36: 上好佳柳橙餡4.5KG | C36: 4.5 | D36: 34 | E36: 34 | F36: 34 | G36: 34.9 | H36: 桶
A37: C7010 | B37: 天天開心芒果餡4.5KG | C37: 4.5 | D37: 31.4 | E37: 31.4 | F37: 33.13 | G37: 33.2 | H37: 桶
A38: C7020 | B38: 上好佳芒果餡(大)4.5KG | C38: 4.5 | G38: 33.2 | H38: 桶
A39: C7021 | B39: 上好佳芒果餡(大)4.5KG | C39: 4.5 | G39: 33.2 | H39: 桶
A40: C9030 | B40: 天天熱帶水果餡 4.5KG | C40: 4.5 | D40: 33.3 | E40: 33.3 | F40: 33.3 | G40: 34.5 | H40: 桶
...

Sheet 資料總表
A1: 日期 | B1: 料號 | C1: 品項 | D1: 鍋數 (P) | E1: 規格 (kg) | F1: 平均均數 (鍋) | G1: 半成品數 (預估) | H1: 半成品數 (實際) | I1: 半成品重量(KG) (實際) | J1: 生產達成率 (實際) | K1: 生產達成率 (目標) | L1: 差異統計 (實際-目標) | M1: 總生產時間(分) | N1: 品保取樣數 | O1: 不良品數 | P1: 成品數 (實際) | Q1: 產品良率 (成品) | R1: 異常單號 | S1: 重工數(kg) | T1: 備註 | U1: 刪除 | V1: 調理繳回單位 | W1: 領料單(調) 交回時間 | X1: 充填繳回單位 | Y1: 領料單(充) 交回時間 | Z1: 充填單位簽核日期 | AA1: 暫存配方 領取時間 | AB1: 暫存配方 回收時間 | AC1: 超過 天數(調) | AD1: 超過 天數(充)
A2: 2024/01/02 | B2: D0230 | C2: =VLOOKUP(B2,'112年全品項生產鍋數'!A:H,2,0) -> 藍莓醬(1*6kg) | D2: 20 | E2: =VLOOKUP(B2,'112年全品項生產鍋數'!A:H,3,0) -> 6 | F2: =VLOOKUP(B2,'112年全品項生產鍋數'!A:H,7,0) -> 25.5 | G2: =D2*F2 -> 510 | H2: 504 | I2: =H2*E2 -> 3024 | J2: =IF(G2=0,"無法預估數據",H2/G2) -> 0.98823529 | K2: =VLOOKUP(B:B,'生產達成率(目標)'!A:C,3,0) -> 1 | L2: =IF(G2=0,"無法預估數據",ROUND(J2-K2,3)) -> -0.012 | O2: =H2-N2-P2 -> 2 | P2: 502 | Q2: =P2/H2 -> 0.99603175 | S2: 2(包)
A3: 2024/01/02 | B3: D0290 | C3: =VLOOKUP(B3,'112年全品項生產鍋數'!A:H,2,0) -> 鳳梨芒果百香果醬(1*6KG) | D3: 12 | E3: =VLOOKUP(B3,'112年全品項生產鍋數'!A:H,3,0) -> 6 | F3: =VLOOKUP(B3,'112年全品項生產鍋數'!A:H,7,0) -> 25.7 | G3: =D3*F3 -> 308.4 | H3: 301 | I3: =H3*E3 -> 1806 | J3: =IF(G3=0,"無法預估數據",H3/G3) -> 0.97600519 | K3: =VLOOKUP(B:B,'生產達成率(目標)'!A:C,3,0) -> 1 | L3: =IF(G3=0,"無法預估數據",ROUND(J3-K3,3)) -> -0.024 | O3: =H3-N3-P3 -> 2 | P3: 299 | Q3: =P3/H3 -> 0.99335548
A4: 2024/01/02 | B4: D0210 | C4: =VLOOKUP(B4,'112年全品項生產鍋數'!A:H,2,0) -> 草莓醬(1*6kg) | D4: 16 | E4: =VLOOKUP(B4,'112年全品項生產鍋數'!A:H,3,0) -> 6 | F4: =VLOOKUP(B4,'112年全品項生產鍋數'!A:H,7,0) -> 26.6 | G4: =D4*F4 -> 425.6 | H4: 412 | I4: =H4*E4 -> 2472 | J4: =IF(G4=0,"無法預估數據",H4/G4) -> 0.96804511 | K4: =VLOOKUP(B:B,'生產達成率(目標)'!A:C,3,0) -> 1 | L4: =IF(G4=0,"無法預估數據",ROUND(J4-K4,3)) -> -0.032 | O4: =H4-N4-P4 -> 2 | P4: 410 | Q4: =P4/H4 -> 0.99514563
A5: 2024/01/02 | B5: C1020 | C5: =VLOOKUP(B5,'112年全品項生產鍋數'!A:H,2,0) -> 天天開心草莓餡4.5KG | D5: 20 | E5: =VLOOKUP(B5,'112年全品項生產鍋數'!A:H,3,0) -> 4.5 | F5: =VLOOKUP(B5,'112年全品項生產鍋數'!A:H,7,0) -> 36.3 | G5: =D5*F5 -> 726 | H5: 713 | I5: =H5*E5 -> 3208.5 | J5: =IF(G5=0,"無法預估數據",H5/G5) -> 0.98209366 | K5: =VLOOKUP(B:B,'生產達成率(目標)'!A:C,3,0) -> 1 | L5: =IF(G5=0,"無法預估數據",ROUND(J5-K5,3)) -> -0.018 | O5: =H5-N5-P5 -> 1 | P5: 712 | Q5: =P5/H5 -> 0.99859748
A6: 2024/01/02 | B6: C9030 | C6: =VLOOKUP(B6,'112年全品項生產鍋數'!A:H,2,0) -> 天天熱帶水果餡 4.5KG | D6: 8 | E6: =VLOOKUP(B6,'112年全品項生產鍋數'!A:H,3,0) -> 4.5 | F6: =VLOOKUP(B6,'112年全品項生產鍋數'!A:H,7,0) -> 34.5 | G6: =D6*F6 -> 276 | H6: 270 | I6: =H6*E6 -> 1215 | J6: =IF(G6=0,"無法預估數據",H6/G6) -> 0.97826087 | K6: =VLOOKUP(B:B,'生產達成率(目標)'!A:C,3,0) -> 1 | L6: =IF(G6=0,"無法預估數據",ROUND(J6-K6,3)) -> -0.022 | O6: =H6-N6-P6 -> 0 | P6: 270 | Q6: =P6/H6 -> 1
A7: 2024/01/02 | B7: D2330 | C7: =VLOOKUP(B7,'112年全品項生產鍋數'!A:H,2,0) -> 蘋果藍莓餡(1*9.08kg) | D7: 24 | E7: =VLOOKUP(B7,'112年全品項生產鍋數'!A:H,3,0) -> 9.08 | F7: =VLOOKUP(B7,'112年全品項生產鍋數'!A:H,7,0) -> 17.3 | G7: =D7*F7 -> 415.2 | H7: 409 | I7: =H7*E7 -> 3713.72 | J7: =IF(G7=0,"無法預估數據",H7/G7) -> 0.98506744 | K7: =VLOOKUP(B:B,'生產達成率(目標)'!A:C,3,0) -> 1 | L7: =IF(G7=0,"無法預估數據",ROUND(J7-K7,3)) -> -0.015 | O7: =H7-N7-P7 -> 0 | P7: 409 | Q7: =P7/H7 -> 1
A8: 2024/01/02 | B8: A2020 | C8: =VLOOKUP(B8,'112年全品項生產鍋數'!A:H,2,0) -> PET大花生(1*400g) | D8: 24 | E8: =VLOOKUP(B8,'112年全品項生產鍋數'!A:H,3,0) -> 0.4 | F8: =VLOOKUP(B8,'112年全品項生產鍋數'!A:H,7,0) -> 309.2 | G8: =D8*F8 -> 7420.8 | H8: 7587 | I8: =H8*E8 -> 3034.8 | J8: =IF(G8=0,"無法預估數據",H8/G8) -> 1.0223965 | K8: =VLOOKUP(B:B,'生產達成率(目標)'!A:C,3,0) -> 1 | L8: =IF(G8=0,"無法預估數據",ROUND(J8-K8,3)) -> 0.022 | O8: =H8-N8-P8 -> 4 | P8: 7583 | Q8: =P8/H8 -> 0.99947278
A9: 2024/01/02 | B9: B2040 | C9: =VLOOKUP(B9,'112年全品項生產鍋數'!A:H,2,0) -> ＃2花生（粒）(1*900g) | D9: 12 | E9: =VLOOKUP(B9,'112年全品項生產鍋數'!A:H,3,0) -> 0.9 | F9: =VLOOKUP(B9,'112年全品項生產鍋數'!A:H,7,0) -> 139.3 | G9: =D9*F9 -> 1671.6 | H9: 1659 | I9: =H9*E9 -> 1493.1 | J9: =IF(G9=0,"無法預估數據",H9/G9) -> 0.99246231 | K9: =VLOOKUP(B:B,'生產達成率(目標)'!A:C,3,0) -> 1 | L9: =IF(G9=0,"無法預估數據",ROUND(J9-K9,3)) -> -0.008 | O9: =H9-N9-P9 -> 2 | P9: 1657 | Q9: =P9/H9 -> 0.99879445 | S9: 61kg
A10: 2024/01/03 | B10: A1020 | C10: =VLOOKUP(B10,'112年全品項生產鍋數'!A:H,2,0) -> 大圓草莓-新 | D10: 24 | E10: =VLOOKUP(B10,'112年全品項生產鍋數'!A:H,3,0) -> 0.44 | F10: =VLOOKUP(B10,'112年全品項生產鍋數'!A:H,7,0) -> 344 | G10: =D10*F10 -> 8256 | H10: 8050 | I10: =H10*E10 -> 3542 | J10: =IF(G10=0,"無法預估數據",H10/G10) -> 0.97504845 | K10: =VLOOKUP(B:B,'生產達成率(目標)'!A:C,3,0) -> 1 | L10: =IF(G10=0,"無法預估數據",ROUND(J10-K10,3)) -> -0.025 | O10: =H10-N10-P10 -> 6 | P10: 8044 | Q10: =P10/H10 -> 0.99925466
A11: 2024/01/03 | B11: D0210 | C11: =VLOOKUP(B11,'112年全品項生產鍋數'!A:H,2,0) -> 草莓醬(1*6kg) | D11: 24 | E11: =VLOOKUP(B11,'112年全品項生產鍋數'!A:H,3,0) -> 6 | F11: =VLOOKUP(B11,'112年全品項生產鍋數'!A:H,7,0) -> 26.6 | G11: =D11*F11 -> 638.4 | H11: 630 | I11: =H11*E11 -> 3780 | J11: =IF(G11=0,"無法預估數據",H11/G11) -> 0.98684211 | K11: =VLOOKUP(B:B,'生產達成率(目標)'!A:C,3,0) -> 1 | L11: =IF(G11=0,"無法預估數據",ROUND(J11-K11,3)) -> -0.013 | O11: =H11-N11-P11 -> 2 | P11: 628 | Q11: =P11/H11 -> 0.9968254 | S11: 5(包)
A12: 2024/01/03 | B12: D0310 | C12: =VLOOKUP(B12,'112年全品項生產鍋數'!A:H,2,0) -> 草莓蒟蒻餡(1*6kg) | D12: 28 | E12: =VLOOKUP(B12,'112年全品項生產鍋數'!A:H,3,0) -> 6 | F12: =VLOOKUP(B12,'112年全品項生產鍋數'!A:H,7,0) -> 25.7 | G12: =D12*F12 -> 719.6 | H12: 709 | I12: =H12*E12 -> 4254 | J12: =IF(G12=0,"無法預估數據",H12/G12) -> 0.98526959 | K12: =VLOOKUP(B:B,'生產達成率(目標)'!A:C,3,0) -> 1 | L12: =IF(G12=0,"無法預估數據",ROUND(J12-K12,3)) -> -0.015 | O12: =H12-N12-P12 -> 5 | P12: 704 | Q12: =P12/H12 -> 0.99294781
A13: 2024/01/03 | B13: D0330 | C13: =VLOOKUP(B13,'112年全品項生產鍋數'!A:H,2,0) -> 藍莓餡(1*6KG) | D13: 20 | E13: =VLOOKUP(B13,'112年全品項生產鍋數'!A:H,3,0) -> 6 | F13: =VLOOKUP(B13,'112年全品項生產鍋數'!A:H,7,0) -> 25.4 | G13: =D13*F13 -> 508 | H13: 487 | I13: =H13*E13 -> 2922 | J13: =IF(G13=0,"無法預估數據",H13/G13) -> 0.95866142 | K13: =VLOOKUP(B:B,'生產達成率(目標)'!A:C,3,0) -> 1 | L13: =IF(G13=0,"無法預估數據",ROUND(J13-K13,3)) -> -0.041 | O13: =H13-N13-P13 -> 4 | P13: 483 | Q13: =P13/H13 -> 0.99178645
A14: 2024/01/03 | B14: B2011 | C14: =VLOOKUP(B14,'112年全品項生產鍋數'!A:H,2,0) -> ＃1花生(1*2.8kg) | D14: 44 | E14: =VLOOKUP(B14,'112年全品項生產鍋數'!A:H,3,0) -> 2.8 | F14: =VLOOKUP(B14,'112年全品項生產鍋數'!A:H,7,0) -> 44.5 | G14: =D14*F14 -> 1958 | H14: 2110 | I14: =H14*E14 -> 5908 | J14: =IF(G14=0,"無法預估數據",H14/G14) -> 1.0776302 | K14: =VLOOKUP(B:B,'生產達成率(目標)'!A:C,3,0) -> 1 | L14: =IF(G14=0,"無法預估數據",ROUND(J14-K14,3)) -> 0.078 | O14: =H14-N14-P14 -> 1 | P14: 2109 | Q14: =P14/H14 -> 0.99952607
A15: 2024/01/03 | B15: B2031 | C15: =VLOOKUP(B15,'112年全品項生產鍋數'!A:H,2,0) -> ＃2花生(1*800g) | D15: 20 | E15: =VLOOKUP(B15,'112年全品項生產鍋數'!A:H,3,0) -> 0.8 | F15: =VLOOKUP(B15,'112年全品項生產鍋數'!A:H,7,0) -> 157.7 | G15: =D15*F15 -> 3154 | H15: 3127 | I15: =H15*E15 -> 2501.6 | J15: =IF(G15=0,"無法預估數據",H15/G15) -> 0.99143944 | K15: =VLOOKUP(B:B,'生產達成率(目標)'!A:C,3,0) -> 1 | L15: =IF(G15=0,"無法預估數據",ROUND(J15-K15,3)) -> -0.009 | O15: =H15-N15-P15 -> 2 | P15: 3125 | Q15: =P15/H15 -> 0.99936041 | S15: 54kg
A16: 2024/01/04 | B16: B1040 | C16: =VLOOKUP(B16,'112年全品項生產鍋數'!A:H,2,0) -> #2草莓果醬(1*900g) | D16: 16.3 | E16: =VLOOKUP(B16,'112年全品項生產鍋數'!A:H,3,0) -> 0.9 | F16: =VLOOKUP(B16,'112年全品項生產鍋數'!A:H,7,0) -> 160.5 | G16: =D16*F16 -> 2616.15 | H16: 2696 | I16: =H16*E16 -> 2426.4 | J16: =IF(G16=0,"無法預估數據",H16/G16) -> 1.030522 | K16: =VLOOKUP(B:B,'生產達成率(目標)'!A:C,3,0) -> 1 | L16: =IF(G16=0,"無法預估數據",ROUND(J16-K16,3)) -> 0.031 | O16: =H16-N16-P16 -> 2 | P16: 2694 | Q16: =P16/H16 -> 0.99925816 | R16: 1130104-01A | T16: 含600美之城
A17: 2024/01/04 | B17: D2010 | C17: =VLOOKUP(B17,'112年全品項生產鍋數'!A:H,2,0) -> 美芝城草莓醬(1*9kg) | D17: 3.7 | E17: =VLOOKUP(B17,'112年全品項生產鍋數'!A:H,3,0) -> 0.9 | F17: =VLOOKUP(B17,'112年全品項生產鍋數'!A:H,7,0) -> 158.7 | G17: =D17*F17 -> 587.19 | H17: 600 | I17: =H17*E17 -> 540 | J17: =IF(G17=0,"無法預估數據",H17/G17) -> 1.0218158 | K17: =VLOOKUP(B:B,'生產達成率(目標)'!A:C,3,0) -> 1 | L17: =IF(G17=0,"無法預估數據",ROUND(J17-K17,3)) -> 0.022 | O17: =H17-N17-P17 -> 0 | P17: 600 | Q17: =P17/H17 -> 1
A18: 2024/01/04 | B18: B1011 | C18: =VLOOKUP(B18,'112年全品項生產鍋數'!A:H,2,0) -> ＃1草莓(1*3.2kg) | D18: 44 | E18: =VLOOKUP(B18,'112年全品項生產鍋數'!A:H,3,0) -> 3.2 | F18: =VLOOKUP(B18,'112年全品項生產鍋數'!A:H,7,0) -> 46.8 | G18: =D18*F18 -> 2059.2 | H18: 2026 | I18: =H18*E18 -> 6483.2 | J18: =IF(G18=0,"無法預估數據",H18/G18) -> 0.98387723 | K18: =VLOOKUP(B:B,'生產達成率(目標)'!A:C,3,0) -> 1 | L18: =IF(G18=0,"無法預估數據",ROUND(J18-K18,3)) -> -0.016 | O18: =H18-N18-P18 -> 3 | P18: 2023 | Q18: =P18/H18 -> 0.99851925
A19: 2024/01/04 | B19: D0113 | C19: =VLOOKUP(B19,'112年全品項生產鍋數'!A:H,2,0) -> 草莓餡45%(1*6Kg) | D19: 20 | E19: =VLOOKUP(B19,'112年全品項生產鍋數'!A:H,3,0) -> 6 | F19: =VLOOKUP(B19,'112年全品項生產鍋數'!A:H,7,0) -> 26.1 | G19: =D19*F19 -> 522 | H19: 517 | I19: =H19*E19 -> 3102 | J19: =IF(G19=0,"無法預估數據",H19/G19) -> 0.99042146 | K19: =VLOOKUP(B:B,'生產達成率(目標)'!A:C,3,0) -> 1 | L19: =IF(G19=0,"無法預估數據",ROUND(J19-K19,3)) -> -0.01 | O19: =H19-N19-P19 -> 1 | P19: 516 | Q19: =P19/H19 -> 0.99806576
A20: 2024/01/04 | B20: D0310 | C20: =VLOOKUP(B20,'112年全品項生產鍋數'!A:H,2,0) -> 草莓蒟蒻餡(1*6kg) | D20: 24 | E20: =VLOOKUP(B20,'112年全品項生產鍋數'!A:H,3,0) -> 6 | F20: =VLOOKUP(B20,'112年全品項生產鍋數'!A:H,7,0) -> 25.7 | G20: =D20*F20 -> 616.8 | H20: 614 | I20: =H20*E20 -> 3684 | J20: =IF(G20=0,"無法預估數據",H20/G20) -> 0.99546044 | K20: =VLOOKUP(B:B,'生產達成率(目標)'!A:C,3,0) -> 1 | L20: =IF(G20=0,"無法預估數據",ROUND(J20-K20,3)) -> -0.005 | O20: =H20-N20-P20 -> 3 | P20: 611 | Q20: =P20/H20 -> 0.99511401
A21: 2024/01/04 | B21: D0121 | C21: =VLOOKUP(B21,'112年全品項生產鍋數'!A:H,2,0) -> 顆粒花生醬(1*12KG) | D21: 24 | E21: =VLOOKUP(B21,'112年全品項生產鍋數'!A:H,3,0) -> 3 | F21: =VLOOKUP(B21,'112年全品項生產鍋數'!A:H,7,0) -> 29.7 | G21: =D21*F21 -> 712.8 | H21: 724 | I21: =H21*E21 -> 2172 | J21: =IF(G21=0,"無法預估數據",H21/G21) -> 1.0157127 | K21: =VLOOKUP(B:B,'生產達成率(目標)'!A:C,3,0) -> 1 | L21: =IF(G21=0,"無法預估數據",ROUND(J21-K21,3)) -> 0.016 | O21: =H21-N21-P21 -> 0 | P21: 724 | Q21: =P21/H21 -> 1
A22: 2024/01/05 | B22: D0210 | C22: =VLOOKUP(B22,'112年全品項生產鍋數'!A:H,2,0) -> 草莓醬(1*6kg) | D22: 48 | E22: =VLOOKUP(B22,'112年全品項生產鍋數'!A:H,3,0) -> 6 | F22: =VLOOKUP(B22,'112年全品項生產鍋數'!A:H,7,0) -> 26.6 | G22: =D22*F22 -> 1276.8 | H22: 1242 | I22: =H22*E22 -> 7452 | J22: =IF(G22=0,"無法預估數據",H22/G22) -> 0.97274436 | K22: =VLOOKUP(B:B,'生產達成率(目標)'!A:C,3,0) -> 1 | L22: =IF(G22=0,"無法預估數據",ROUND(J22-K22,3)) -> -0.027 | O22: =H22-N22-P22 -> 8 | P22: 1234 | Q22: =P22/H22 -> 0.99355878 | S22: 1(包)
A23: 2024/01/05 | B23: D0114 | C23: =VLOOKUP(B23,'112年全品項生產鍋數'!A:H,2,0) -> 草莓椰果餡(1*6Kg) | D23: 16 | E23: =VLOOKUP(B23,'112年全品項生產鍋數'!A:H,3,0) -> 6 | F23: =VLOOKUP(B23,'112年全品項生產鍋數'!A:H,7,0) -> 26.4 | G23: =D23*F23 -> 422.4 | H23: 424 | I23: =H23*E23 -> 2544 | J23: =IF(G23=0,"無法預估數據",H23/G23) -> 1.0037879 | K23: =VLOOKUP(B:B,'生產達成率(目標)'!A:C,3,0) -> 1 | L23: =IF(G23=0,"無法預估數據",ROUND(J23-K23,3)) -> 0.004 | O23: =H23-N23-P23 -> 2 | P23: 422 | Q23: =P23/H23 -> 0.99528302
A24: 2024/01/05 | B24: D0111 | C24: =VLOOKUP(B24,'112年全品項生產鍋數'!A:H,2,0) -> 草莓餡(1*6Kg) | D24: 20 | E24: =VLOOKUP(B24,'112年全品項生產鍋數'!A:H,3,0) -> 6 | F24: =VLOOKUP(B24,'112年全品項生產鍋數'!A:H,7,0) -> 25.5 | G24: =D24*F24 -> 510 | H24: 509 | I24: =H24*E24 -> 3054 | J24: =IF(G24=0,"無法預估數據",H24/G24) -> 0.99803922 | K24: =VLOOKUP(B:B,'生產達成率(目標)'!A:C,3,0) -> 1 | L24: =IF(G24=0,"無法預估數據",ROUND(J24-K24,3)) -> -0.002 | O24: =H24-N24-P24 -> 1 | P24: 508 | Q24: =P24/H24 -> 0.99803536
A25: 2024/01/05 | B25: D0610 | C25: =VLOOKUP(B25,'112年全品項生產鍋數'!A:H,2,0) -> 草莓餡50°(1*6Kg) | D25: 16 | E25: =VLOOKUP(B25,'112年全品項生產鍋數'!A:H,3,0) -> 6 | F25: =VLOOKUP(B25,'112年全品項生產鍋數'!A:H,7,0) -> 25 | G25: =D25*F25 -> 400 | H25: 404 | I25: =H25*E25 -> 2424 | J25: =IF(G25=0,"無法預估數據",H25/G25) -> 1.01 | K25: =VLOOKUP(B:B,'生產達成率(目標)'!A:C,3,0) -> 1 | L25: =IF(G25=0,"無法預估數據",ROUND(J25-K25,3)) -> 0.01 | O25: =H25-N25-P25 -> 1 | P25: 403 | Q25: =P25/H25 -> 0.99752475
A26: 2024/01/05 | B26: B2011 | C26: =VLOOKUP(B26,'112年全品項生產鍋數'!A:H,2,0) -> ＃1花生(1*2.8kg) | D26: 72 | E26: =VLOOKUP(B26,'112年全品項生產鍋數'!A:H,3,0) -> 2.8 | F26: =VLOOKUP(B26,'112年全品項生產鍋數'!A:H,7,0) -> 44.5 | G26: =D26*F26 -> 3204 | H26: 3456 | I26: =H26*E26 -> 9676.8 | J26: =IF(G26=0,"無法預估數據",H26/G26) -> 1.0786517 | K26: =VLOOKUP(B:B,'生產達成率(目標)'!A:C,3,0) -> 1 | L26: =IF(G26=0,"無法預估數據",ROUND(J26-K26,3)) -> 0.079 | O26: =H26-N26-P26 -> 1 | P26: 3455 | Q26: =P26/H26 -> 0.99971065 | S26: 69.3kg
A27: 2024/01/06 | B27: B1011 | C27: =VLOOKUP(B27,'112年全品項生產鍋數'!A:H,2,0) -> ＃1草莓(1*3.2kg) | D27: 88 | E27: =VLOOKUP(B27,'112年全品項生產鍋數'!A:H,3,0) -> 3.2 | F27: =VLOOKUP(B27,'112年全品項生產鍋數'!A:H,7,0) -> 46.8 | G27: =D27*F27 -> 4118.4 | H27: 4090 | I27: =H27*E27 -> 13088 | J27: =IF(G27=0,"無法預估數據",H27/G27) -> 0.99310412 | K27: =VLOOKUP(B:B,'生產達成率(目標)'!A:C,3,0) -> 1 | L27: =IF(G27=0,"無法預估數據",ROUND(J27-K27,3)) -> -0.007 | O27: =H27-N27-P27 -> 2 | P27: 4088 | Q27: =P27/H27 -> 0.999511 | R27: 1130106-02A
A28: 2024/01/06 | B28: D0310 | C28: =VLOOKUP(B28,'112年全品項生產鍋數'!A:H,2,0) -> 草莓蒟蒻餡(1*6kg) | D28: 40 | E28: =VLOOKUP(B28,'112年全品項生產鍋數'!A:H,3,0) -> 6 | F28: =VLOOKUP(B28,'112年全品項生產鍋數'!A:H,7,0) -> 25.7 | G28: =D28*F28 -> 1028 | H28: 990 | I28: =H28*E28 -> 5940 | J28: =IF(G28=0,"無法預估數據",H28/G28) -> 0.96303502 | K28: =VLOOKUP(B:B,'生產達成率(目標)'!A:C,3,0) -> 1 | L28: =IF(G28=0,"無法預估數據",ROUND(J28-K28,3)) -> -0.037 | O28: =H28-N28-P28 -> 5 | P28: 985 | Q28: =P28/H28 -> 0.99494949
A29: 2024/01/08 | B29: B5011 | C29: =VLOOKUP(B29,'112年全品項生產鍋數'!A:H,2,0) -> ＃1桔子(1*3.2kg) | D29: 36 | E29: =VLOOKUP(B29,'112年全品項生產鍋數'!A:H,3,0) -> 3.2 | F29: =VLOOKUP(B29,'112年全品項生產鍋數'!A:H,7,0) -> 46.4 | G29: =D29*F29 -> 1670.4 | H29: 1710 | I29: =H29*E29 -> 5472 | J29: =IF(G29=0,"無法預估數據",H29/G29) -> 1.0237069 | K29: =VLOOKUP(B:B,'生產達成率(目標)'!A:C,3,0) -> 1 | L29: =IF(G29=0,"無法預估數據",ROUND(J29-K29,3)) -> 0.024 | O29: =H29-N29-P29 -> 2 | P29: 1708 | Q29: =P29/H29 -> 0.99883041
A30: 2024/01/08 | B30: D0310 | C30: =VLOOKUP(B30,'112年全品項生產鍋數'!A:H,2,0) -> 草莓蒟蒻餡(1*6kg) | D30: 24 | E30: =VLOOKUP(B30,'112年全品項生產鍋數'!A:H,3,0) -> 6 | F30: =VLOOKUP(B30,'112年全品項生產鍋數'!A:H,7,0) -> 25.7 | G30: =D30*F30 -> 616.8 | H30: 610 | I30: =H30*E30 -> 3660 | J30: =IF(G30=0,"無法預估數據",H30/G30) -> 0.98897536 | K30: =VLOOKUP(B:B,'生產達成率(目標)'!A:C,3,0) -> 1 | L30: =IF(G30=0,"無法預估數據",ROUND(J30-K30,3)) -> -0.011 | O30: =H30-N30-P30 -> 3 | P30: 607 | Q30: =P30/H30 -> 0.99508197
A31: 2024/01/08 | B31: D0131 | C31: =VLOOKUP(B31,'112年全品項生產鍋數'!A:H,2,0) -> 藍莓餡(1*6Kg) | D31: 20 | E31: =VLOOKUP(B31,'112年全品項生產鍋數'!A:H,3,0) -> 6 | F31: =VLOOKUP(B31,'112年全品項生產鍋數'!A:H,7,0) -> 25.1 | G31: =D31*F31 -> 502 | H31: 503 | I31: =H31*E31 -> 3018 | J31: =IF(G31=0,"無法預估數據",H31/G31) -> 1.001992 | K31: =VLOOKUP(B:B,'生產達成率(目標)'!A:C,3,0) -> 1 | L31: =IF(G31=0,"無法預估數據",ROUND(J31-K31,3)) -> 0.002 | O31: =H31-N31-P31 -> 2 | P31: 501 | Q31: =P31/H31 -> 0.99602386
A32: 2024/01/08 | B32: A2060 | C32: =VLOOKUP(B32,'112年全品項生產鍋數'!A:H,2,0) -> 顆粒花生醬(全) | D32: 36 | E32: =VLOOKUP(B32,'112年全品項生產鍋數'!A:H,3,0) -> 0.34 | F32: =VLOOKUP(B32,'112年全品項生產鍋數'!A:H,7,0) -> 364.6 | G32: =D32*F32 -> 13125.6 | H32: 12829 | I32: =H32*E32 -> 4361.86 | J32: =IF(G32=0,"無法預估數據",H32/G32) -> 0.97740294 | K32: =VLOOKUP(B:B,'生產達成率(目標)'!A:C,3,0) -> 1 | L32: =IF(G32=0,"無法預估數據",ROUND(J32-K32,3)) -> -0.023 | O32: =H32-N32-P32 -> 3 | P32: 12826 | Q32: =P32/H32 -> 0.99976615
A33: 2024/01/08 | B33: A2050 | C33: =VLOOKUP(B33,'112年全品項生產鍋數'!A:H,2,0) -> PET瓶花生(粒)(1*340g) | D33: 4.88 | E33: =VLOOKUP(B33,'112年全品項生產鍋數'!A:H,3,0) -> 0.34 | F33: =VLOOKUP(B33,'112年全品項生產鍋數'!A:H,7,0) -> 366 | G33: =D33*F33 -> 1786.08 | H33: 1721 | I33: =H33*E33 -> 585.14 | J33: =IF(G33=0,"無法預估數據",H33/G33) -> 0.96356266 | K33: =VLOOKUP(B:B,'生產達成率(目標)'!A:C,3,0) -> 1 | L33: =IF(G33=0,"無法預估數據",ROUND(J33-K33,3)) -> -0.036 | O33: =H33-N33-P33 -> 5 | P33: 1716 | Q33: =P33/H33 -> 0.99709471 | S33: 43kg | T33: 含佳樂美200箱
A34: 2024/01/08 | B34: E0121 | C34: =VLOOKUP(B34,'112年全品項生產鍋數'!A:H,2,0) -> 佳樂美花生醬(粒)(1*340g) | D34: 7.12 | E34: =VLOOKUP(B34,'112年全品項生產鍋數'!A:H,3,0) -> 0.34 | F34: =VLOOKUP(B34,'112年全品項生產鍋數'!A:H,7,0) -> 366 | G34: =D34*F34 -> 2605.92 | H34: 2640 | I34: =H34*E34 -> 897.6 | J34: =IF(G34=0,"無法預估數據",H34/G34) -> 1.0130779 | K34: 1 | L34: =IF(G34=0,"無法預估數據",ROUND(J34-K34,3)) -> 0.013 | O34: =H34-N34-P34 -> 0 | P34: 2640 | Q34: =P34/H34 -> 1
A35: 2024/01/09 | B35: B3020 | C35: =VLOOKUP(B35,'112年全品項生產鍋數'!A:H,2,0) -> ＃2藍莓(1*900g) | D35: 20 | E35: =VLOOKUP(B35,'112年全品項生產鍋數'!A:H,3,0) -> 0.9 | F35: =VLOOKUP(B35,'112年全品項生產鍋數'!A:H,7,0) -> 163 | G35: =D35*F35 -> 3260 | H35: 3399 | I35: =H35*E35 -> 3059.1 | J35: =IF(G35=0,"無法預估數據",H35/G35) -> 1.042638 | K35: =VLOOKUP(B:B,'生產達成率(目標)'!A:C,3,0) -> 1 | L35: =IF(G35=0,"無法預估數據",ROUND(J35-K35,3)) -> 0.043 | O35: =H35-N35-P35 -> 2 | P35: 3397 | Q35: =P35/H35 -> 0.99941159 | S35: 1(包)
A36: 2024/01/09 | B36: B3011 | C36: =VLOOKUP(B36,'112年全品項生產鍋數'!A:H,2,0) -> ＃1藍莓(1*3.2kg) | D36: 36 | E36: =VLOOKUP(B36,'112年全品項生產鍋數'!A:H,3,0) -> 3.2 | F36: =VLOOKUP(B36,'112年全品項生產鍋數'!A:H,7,0) -> 47.5 | G36: =D36*F36 -> 1710 | H36: 1666 | I36: =H36*E36 -> 5331.2 | J36: =IF(G36=0,"無法預估數據",H36/G36) -> 0.97426901 | K36: =VLOOKUP(B:B,'生產達成率(目標)'!A:C,3,0) -> 1 | L36: =IF(G36=0,"無法預估數據",ROUND(J36-K36,3)) -> -0.026 | O36: =H36-N36-P36 -> 1 | P36: 1665 | Q36: =P36/H36 -> 0.99939976 | S36: 2(包)
A37: 2024/01/09 | B37: D2212 | C37: =VLOOKUP(B37,'112年全品項生產鍋數'!A:H,2,0) -> 草莓餡(1*6KG) | D37: 40 | E37: =VLOOKUP(B37,'112年全品項生產鍋數'!A:H,3,0) -> 6 | F37: =VLOOKUP(B37,'112年全品項生產鍋數'!A:H,7,0) -> 25.5 | G37: =D37*F37 -> 1020 | H37: 1028 | I37: =H37*E37 -> 6168 | J37: =IF(G37=0,"無法預估數據",H37/G37) -> 1.0078431 | K37: =VLOOKUP(B:B,'生產達成率(目標)'!A:C,3,0) -> 1 | L37: =IF(G37=0,"無法預估數據",ROUND(J37-K37,3)) -> 0.008 | O37: =H37-N37-P37 -> 1 | P37: 1027 | Q37: =P37/H37 -> 0.99902724
A38: 2024/01/09 | B38: D9920 | C38: =VLOOKUP(B38,'112年全品項生產鍋數'!A:H,2,0) -> 花生醬（1*18kg) | D38: 9 | E38: =VLOOKUP(B38,'112年全品項生產鍋數'!A:H,3,0) -> 18 | F38: =VLOOKUP(B38,'112年全品項生產鍋數'!A:H,7,0) -> 6.7 | G38: =D38*F38 -> 60.3 | H38: 60 | I38: =H38*E38 -> 1080 | J38: =IF(G38=0,"無法預估數據",H38/G38) -> 0.99502488 | K38: =VLOOKUP(B:B,'生產達成率(目標)'!A:C,3,0) -> 1 | L38: =IF(G38=0,"無法預估數據",ROUND(J38-K38,3)) -> -0.005 | O38: =H38-N38-P38 -> 0 | P38: 60 | Q38: =P38/H38 -> 1
A39: 2024/01/09 | B39: B2011 | C39: =VLOOKUP(B39,'112年全品項生產鍋數'!A:H,2,0) -> ＃1花生(1*2.8kg) | D39: 50 | E39: =VLOOKUP(B39,'112年全品項生產鍋數'!A:H,3,0) -> 2.8 | F39: =VLOOKUP(B39,'112年全品項生產鍋數'!A:H,7,0) -> 44.5 | G39: =D39*F39 -> 2225 | H39: 2502 | I39: =H39*E39 -> 7005.6 | J39: =IF(G39=0,"無法預估數據",H39/G39) -> 1.1244944 | K39: =VLOOKUP(B:B,'生產達成率(目標)'!A:C,3,0) -> 1 | L39: =IF(G39=0,"無法預估數據",ROUND(J39-K39,3)) -> 0.124 | O39: =H39-N39-P39 -> 1 | P39: 2501 | Q39: =P39/H39 -> 0.99960032 | S39: 65kg
A40: 2024/01/10 | B40: A1020 | C40: =VLOOKUP(B40,'112年全品項生產鍋數'!A:H,2,0) -> 大圓草莓-新 | D40: 24 | E40: =VLOOKUP(B40,'112年全品項生產鍋數'!A:H,3,0) -> 0.44 | F40: =VLOOKUP(B40,'112年全品項生產鍋數'!A:H,7,0) -> 344 | G40: =D40*F40 -> 8256 | H40: 8071 | I40: =H40*E40 -> 3551.24 | J40: =IF(G40=0,"無法預估數據",H40/G40) -> 0.97759205 | K40: =VLOOKUP(B:B,'生產達成率(目標)'!A:C,3,0) -> 1 | L40: =IF(G40=0,"無法預估數據",ROUND(J40-K40,3)) -> -0.022 | O40: =H40-N40-P40 -> 9 | P40: 8062 | Q40: =P40/H40 -> 0.9988849
...

Sheet 工時
A1: 日期 | B1: 料號 | C1: 品項 | D1: 鍋數 (P) | E1: 人數 | F1: 前置作業 | G1: 生產開始時間 | H1: 生產結束時間 | I1: 生產時間(分) | J1: 人數 | K1: 前置作業 | L1: 生產開始時間 | M1: 生產結束時間 | N1: 生產時間(分) | O1: 生產時間*人數 | P1: 開始 | Q1: 結束 | R1: 總生產時間(分) | S1: 中午
E2: 製造 | J2: 充填 | S2: 0.5 | T2: 0.54166667
A3: 10/14 | B3: B1011 | C3: ＃1草莓(1*3.2kg) | D3: 72 | E3: 6 | G3: 0.29166667 | H3: 0.66666667 | I3: 480 | J3: 6 | L3: 0.3125 | M3: 0.70833333 | N3: 510 | O3: 5940 | P3: 0.29166667 | Q3: 0.70833333 | R3: 540
A4: 10/14 | B4: D0113 | C4: 草莓餡45%(1*6Kg) | D4: 20 | E4: 5 | G4: 0.37708333 | H4: 0.58333333 | I4: 237 | J4: 3 | K4: 0.0055555556 | L4: 0.39583333 | M4: 0.61458333 | N4: 263 | O4: 1974 | P4: 0.37708333 | Q4: 0.61458333 | R4: 282
A5: 10/14 | B5: D0292 | C5: 蜂蜜柚香醬(1*6KG) | D5: 8 | E5: 5 | G5: 0.29166667 | H5: 0.375 | I5: 120 | J5: 3 | K5: 0.0055555556 | L5: 0.32986111 | M5: 0.39583333 | N5: 103 | O5: 909 | P5: 0.29166667 | Q5: 0.39583333 | R5: 150
A6: 10/14 | B6: D0230 | C6: 藍莓醬(1*6kg) | D6: 16 | E6: 5 | G6: 0.58680556 | H6: 0.72916667 | I6: 205 | J6: 3 | K6: 0.0055555556 | L6: 0.61458333 | M6: 0.72916667 | N6: 173 | O6: 1544 | P6: 0.58680556 | Q6: 0.72916667 | R6: 205
A7: 10/14 | B7: B2011 | C7: ＃1花生(1*2.8kg) | D7: 72 | E7: 3 | F7: 0.027777778 | G7: 0.40625 | H7: 0.48611111 | I7: 155 | J7: 4 | L7: 0.27083333 | M7: 0.79861111 | N7: 700 | O7: 3265 | P7: 0.27083333 | Q7: 0.79861111 | R7: 700
A8: 10/14 | B8: D1791 | C8: 柚皮糖 | D8: 1 | I8: 0 | N8: 0 | O8: 0 | P8: 0 | Q8: 0 | R8: 0
A9: 10/15 | B9: D0210 | C9: 草莓醬(1*6kg) | D9: 20 | E9: 5 | G9: 0.54166667 | H9: 0.6875 | I9: 210 | J9: 3 | L9: 0.56597222 | M9: 0.70833333 | N9: 205 | O9: 1665 | P9: 0.54166667 | Q9: 0.70833333 | R9: 240
A10: 10/15 | B10: D0197 | C10: 檸檬餡(1*6Kg) | D10: 24 | E10: 5 | G10: 0.29166667 | H10: 0.48263889 | I10: 275 | J10: 3 | L10: 0.3125 | M10: 0.55902778 | N10: 295 | O10: 2260 | P10: 0.29166667 | Q10: 0.55902778 | R10: 325
A11: 10/15 | B11: D0120 | C11: 顆粒花生醬(1*12KG) | D11: 21 | G11: 0.32638889 | H11: 0.5625 | I11: 280 | L11: 0.5625 | M11: 0.70833333 | N11: 210 | O11: 0 | P11: 0.32638889 | Q11: 0.70833333 | R11: 490
A12: 10/15 | B12: A2020 | C12: PET大花生(1*400g) | D12: 36 | E12: 3 | F12: 0.020833333 | G12: 0.27083333 | H12: 0.70833333 | I12: 600 | J12: 6 | L12: 0.29166667 | M12: 0.64583333 | N12: 450 | O12: 4500 | P12: 0.27083333 | Q12: 0.70833333 | R12: 570
A13: 10/15 | B13: 152010 | C13: 蜜綠果6m/m | D13: 0.5 | I13: 0 | N13: 0 | O13: 0 | P13: 0 | Q13: 0 | R13: 0
A14: 10/16 | B14: B1011 | C14: ＃1草莓(1*3.2kg) | D14: 72 | E14: 6 | G14: 0.29166667 | H14: 0.66666667 | I14: 480 | J14: 5 | L14: 0.3125 | M14: 0.70833333 | N14: 510 | O14: 5430 | P14: 0.29166667 | Q14: 0.70833333 | R14: 540
A15: 10/16 | B15: D0310 | C15: 草莓蒟蒻餡(1*6kg) | D15: 20 | E15: 5 | G15: 0.54166667 | H15: 0.70694444 | I15: 238 | J15: 4 | L15: 0.56944444 | M15: 0.71527778 | N15: 210 | O15: 2030 | P15: 0.54166667 | Q15: 0.71527778 | R15: 250
A16: 10/16 | B16: D2813 | C16: 草莓醬(1*6Kg) | D16: 12 | E16: 5 | G16: 0.40972222 | H16: 0.49791667 | I16: 127 | J16: 4 | L16: 0.43055556 | M16: 0.56944444 | N16: 140 | O16: 1195 | P16: 0.40972222 | Q16: 0.56944444 | R16: 170
A17: 10/16 | B17: D0131 | C17: 藍莓餡(1*6Kg) | D17: 12 | E17: 5 | G17: 0.29166667 | H17: 0.40625 | I17: 165 | J17: 3 | L17: 0.3125 | M17: 0.41666667 | N17: 150 | O17: 1275 | P17: 0.29166667 | Q17: 0.41666667 | R17: 180
A18: 10/16 | B18: B2011 | C18: ＃1花生(1*2.8kg) | D18: 72 | E18: 3 | F18: 0.083333333 | G18: 0.29166667 | H18: 0.75 | I18: 720 | J18: 4 | L18: 0.29166667 | M18: 0.79166667 | N18: 660 | O18: 4800 | P18: 0.29166667 | Q18: 0.79166667 | R18: 660
A19: 10/17 | B19: A1040 | C19: 開心草莓果醬(1*430g) | D19: 15 | E19: 4 | G19: 0.29166667 | H19: 0.49861111 | I19: 298 | J19: 12 | L19: 0.3125 | M19: 0.58333333 | N19: 330 | O19: 5152 | P19: 0.29166667 | Q19: 0.58333333 | R19: 360
A20: 10/17 | B20: A1050 | C20: 梨山草莓果醬(1*430g) | D20: 12 | E20: 2 | G20: 0.52083333 | H20: 0.66666667 | I20: 210 | J20: 9 | L20: 0.58333333 | M20: 0.70833333 | N20: 180 | O20: 2040 | P20: 0.52083333 | Q20: 0.70833333 | R20: 270
A21: 10/17 | B21: D0132 | C21: 綜合莓果餡(1*6Kg) | D21: 4 | E21: 5 | G21: 0.40625 | H21: 0.44791667 | I21: 60 | J21: 3 | L21: 0.44791667 | M21: 0.5 | N21: 75 | O21: 525 | P21: 0.40625 | Q21: 0.5 | R21: 135
A22: 10/17 | B22: D0290 | C22: 鳳梨芒果百香果醬(1*6KG) | D22: 12 | E22: 5 | G22: 0.29166667 | H22: 0.40277778 | I22: 160 | J22: 3 | L22: 0.3125 | M22: 0.43402778 | N22: 175 | O22: 1325 | P22: 0.29166667 | Q22: 0.43402778 | R22: 205
A23: 10/17 | B23: D0310 | C23: 草莓蒟蒻餡(1*6kg) | D23: 24 | E23: 5 | G23: 0.54166667 | H23: 0.74652778 | I23: 295 | J23: 3 | L23: 0.54166667 | M23: 0.75 | N23: 300 | O23: 2375 | P23: 0.54166667 | Q23: 0.75 | R23: 300
A24: 10/17 | B24: B2031 | C24: ＃2花生(1*800g) | D24: 40 | E24: 3 | F24: 0.020833333 | G24: 0.29166667 | H24: 0.64583333 | I24: 480 | J24: 4 | L24: 0.29166667 | M24: 0.70833333 | N24: 540 | O24: 3600 | P24: 0.29166667 | Q24: 0.70833333 | R24: 540
A25: 10/18 | B25: B5011 | C25: ＃1桔子(1*3.2kg) | D25: 72 | E25: 6 | G25: 0.29166667 | H25: 0.66666667 | I25: 480 | J25: 5 | L25: 0.3125 | M25: 0.70833333 | N25: 510 | O25: 5430 | P25: 0.29166667 | Q25: 0.70833333 | R25: 540
A26: 10/18 | B26: D0121 | C26: 顆粒花生醬(1*12KG) | D26: 21 | E26: 4 | G26: 0.29166667 | H26: 0.61111111 | I26: 400 | J26: 8 | L26: 0.39583333 | M26: 0.70833333 | N26: 390 | O26: 4720 | P26: 0.29166667 | Q26: 0.70833333 | R26: 540
A27: 10/18 | B27: B2011 | C27: ＃1花生(1*2.8kg) | D27: 72 | E27: 3 | F27: 0.083333333 | G27: 0.29166667 | H27: 0.75 | I27: 720 | J27: 4 | L27: 0.29166667 | M27: 0.79166667 | N27: 660 | O27: 4800 | P27: 0.29166667 | Q27: 0.79166667 | R27: 660
A28: 10/21 | B28: A1020 | C28: 大圓草莓-新 | D28: 24 | E28: 4 | G28: 0.29166667 | H28: 0.5 | I28: 300 | J28: 10 | K28: 0.0069444444 | L28: 0.33333333 | M28: 0.57291667 | N28: 295 | O28: 4150 | P28: 0.29166667 | Q28: 0.57291667 | R28: 345
A29: 10/21 | B29: A3011 | C29: 小藍莓1*260G | D29: 4 | E29: 4 | G29: 0.54166667 | H29: 0.72916667 | I29: 270 | J29: 9 | K29: 0.0069444444 | L29: 0.66666667 | M29: 0.75 | N29: 130 | O29: 2250 | P29: 0.54166667 | Q29: 0.75 | R29: 300
A30: 10/21 | B30: A3010 | C30: 小藍莓1*260G | D30: 12 | E30: 4 | G30: 0.54166667 | H30: 0.72916667 | I30: 270 | J30: 9 | K30: 0.0069444444 | L30: 0.57291667 | M30: 0.66666667 | N30: 145 | O30: 2385 | P30: 0.54166667 | Q30: 0.72916667 | R30: 270
A31: 10/21 | B31: D2531 | C31: 特殊藍莓餡(1*9.08kg) | D31: 12 | E31: 5 | G31: 0.29166667 | H31: 0.42013889 | I31: 185 | J31: 3 | K31: 0.010416667 | L31: 0.33333333 | M31: 0.45138889 | N31: 185 | O31: 1480 | P31: 0.29166667 | Q31: 0.45138889 | R31: 230
A32: 10/21 | B32: D2212 | C32: 草莓餡(1*6KG) | D32: 32 | E32: 5 | G32: 0.42152778 | H32: 0.77083333 | I32: 443 | J32: 3 | K32: 0.010416667 | L32: 0.45138889 | M32: 0.77083333 | N32: 415 | O32: 3460 | P32: 0.42152778 | Q32: 0.77083333 | R32: 443
A33: 10/21 | B33: D0121 | C33: 顆粒花生醬(1*12KG) | D33: 21 | E33: 8 | F33: 0.020833333 | G33: 0.29166667 | H33: 0.70833333 | I33: 570 | J33: 8 | L33: 0.29166667 | M33: 0.70833333 | N33: 540 | O33: 8880 | P33: 0.29166667 | Q33: 0.70833333 | R33: 540
A34: 10/21 | B34: 153010 | C34: 蜜桔皮6m/m | D34: 1 | I34: 0 | N34: 0 | O34: 0 | P34: 0 | Q34: 0 | R34: 0
A35: 10/22 | B35: B1011 | C35: ＃1草莓(1*3.2kg) | D35: 72 | E35: 6 | G35: 0.29166667 | H35: 0.66666667 | I35: 480 | J35: 5 | K35: 0.041666667 | L35: 0.3125 | M35: 0.70833333 | N35: 570 | O35: 5730 | P35: 0.29166667 | Q35: 0.70833333 | R35: 540
A36: 10/22 | B36: D0310 | C36: 草莓蒟蒻餡(1*6kg) | D36: 24 | E36: 5 | G36: 0.54166667 | H36: 0.75 | I36: 300 | J36: 3 | K36: 0.010416667 | L36: 0.5625 | M36: 0.75 | N36: 285 | O36: 2355 | P36: 0.54166667 | Q36: 0.75 | R36: 300
A37: 10/22 | B37: D0330 | C37: 藍莓餡(1*6KG) | D37: 24 | E37: 5 | G37: 0.29166667 | H37: 0.5 | I37: 300 | J37: 3 | K37: 0.010416667 | L37: 0.33333333 | M37: 0.5625 | N37: 285 | O37: 2355 | P37: 0.29166667 | Q37: 0.5625 | R37: 330
A38: 10/22 | B38: B2021 | C38: ＃1花生(粒)(1*2.8kg) | D38: 72 | E38: 3 | F38: 0.083333333 | G38: 0.29166667 | H38: 0.72916667 | I38: 690 | J38: 4 | L38: 0.29166667 | M38: 0.72916667 | N38: 570 | O38: 4350 | P38: 0.29166667 | Q38: 0.72916667 | R38: 570
A39: 10/23 | B39: D0210 | C39: 草莓醬(1*6kg) | D39: 30 | E39: 5 | G39: 0.40277778 | H39: 0.72916667 | I39: 410 | J39: 4 | K39: 0.010416667 | L39: 0.4375 | M39: 0.77083333 | N39: 435 | O39: 3790 | P39: 0.40277778 | Q39: 0.77083333 | R39: 470
A40: 10/23 | B40: D0250 | C40: 葡萄奇異果醬(1*6kg) | D40: 12 | E40: 5 | G40: 0.29166667 | H40: 0.40277778 | I40: 160 | J40: 3 | K40: 0.010416667 | L40: 0.33333333 | M40: 0.4375 | N40: 165 | O40: 1295 | P40: 0.29166667 | Q40: 0.4375 | R40: 210
...

Sheet 領料單繳回統計
B1: 調理
B4: 日期 | C4: 組別 | D4: 料號 | E4: 品項 | F4: 領料單(調) | G4: 調理繳回超過7天
B5: 總計
B12: 充填
B15: 日期 | C15: 組別 | D15: 料號 | E15: 品項 | F15: 領料單(調) | G15: 充填繳回超過7天
B16: 46196 | C16: 果醬班 | D16: D0210 | E16: 草莓醬(1*6kg) | F16: 46196 | G16: 8
D17: D0230 | E17: 藍莓醬(1*6kg) | F17: 46196 | G17: 8
B18: 46197 | C18: 果餡班 | D18: D0113 | E18: 草莓餡45%(1*6Kg) | F18: 46197 | G18: 7
D19: D0310 | E19: 草莓蒟蒻餡(1*6kg) | F19: 46198 | G19: 7
C20: 果醬班 | D20: B1040 | E20: #2草莓果醬(1*900g) | F20: 46197 | G20: 7
D21: B3011 | E21: ＃1藍莓(1*3.2kg) | F21: 46197 | G21: 7
B22: 46198 | C22: 果餡班 | D22: D0310 | E22: 草莓蒟蒻餡(1*6kg) | F22: 46198 | G22: 8
D23: D0331 | E23: 藍莓餡(1*6KG) | F23: 46198 | G23: 8
B24: 46212 | C24: 果餡班 | D24: D2712 | E24: 草莓果醬(1*6KG) | F24: 46218 | G24: 7
B25: 總計
